<?xml version="1.0" ?>
<robot xmlns:xacro="http://ros.org/wiki/xacro">

  <!--
  <xacro:property name="pi" value="3.141592654" />
  -->

  <!-- left leg -->
  <xacro:macro name="humanoid_l_arm" params="parent">

  <!-- left shoulder pitch joint -->
  <joint name="l_sho_pitch" type="revolute">
    <parent link="${parent}"/>
    <child link="l_sho_pitch_link"/>
    <origin xyz="0.000034 0.177209 0.276882" rpy="0 0 0" />
    <axis xyz="0 1 0" />
    <limit effort="10" velocity="5" lower="${-pi}" upper="${1.0472}" />
    <dynamics damping="0.1" friction="0.0" />
  </joint>
  <xacro:insert_transmission name="l_sho_pitch" />

  <!-- left shoulder pitch link -->
  <link name="l_sho_pitch_link">
    <visual>
      <xacro:insert_mesh_l_sho_pitch_link />
    </visual>
    <collision>
      <xacro:insert_meshcol_l_sho_pitch_link />
    </collision>
    <inertial>
      <xacro:insert_inertia_l_sho_pitch_link />
    </inertial>
  </link>

  <!-- left shoulder roll joint -->
  <joint name="l_sho_roll" type="revolute">
    <parent link="l_sho_pitch_link"/>
    <child link="l_sho_roll_link"/>
    <origin xyz="0.02506 0.049194 -0.026717" rpy="0 0 0" />
    <axis xyz="1 0 0" />
    <limit effort="10" velocity="5" lower="${-0.174533}" upper="${pi/2}" />
    <dynamics damping="0.1" friction="0.0" />
  </joint>
  <xacro:insert_transmission name="l_sho_roll" />

  <!-- left shoulder roll link -->
  <link name="l_sho_roll_link">
    <visual>
      <xacro:insert_mesh_l_sho_roll_link />
    </visual>
    <collision>
      <xacro:insert_meshcol_l_sho_roll_link />
    </collision>
    <inertial>
      <xacro:insert_inertia_l_sho_roll_link />
    </inertial>
  </link>

  <!-- left elbow joint -->
  <joint name="l_el" type="revolute">
    <parent link="l_sho_roll_link"/>
    <child link="l_el_link"/>
    <origin xyz="-0.0079 -0.0245 -0.207906" rpy="0 0 0" />
    <axis xyz="0 1 0" />
    <limit effort="10" velocity="5" lower="${-2.79253}" upper="${0}" />
    <dynamics damping="0.1" friction="0.0" />
  </joint>
  <xacro:insert_transmission name="l_el" />

  <!-- left elbow link -->
  <link name="l_el_link">
    <visual>
      <xacro:insert_mesh_l_el_link />
    </visual>
    <collision>
      <xacro:insert_meshcol_l_el_link />
    </collision>
    <inertial>
      <xacro:insert_inertia_l_el_link />
    </inertial>
  </link>

  <!-- left elbow yaw joint -->
  <joint name="l_el_yaw" type="revolute">
    <parent link="l_el_link"/>
    <child link="l_el_yaw_link"/>
    <origin xyz="-0.0155 0.0245 -0.078296" rpy="0 0 0" />
    <axis xyz="0 0 1" />
    <limit effort="10" velocity="5" lower="${-pi}" upper="${pi}" />
    <dynamics damping="0.1" friction="0.0" />
  </joint>
  <xacro:insert_transmission name="l_el_yaw" />

  <!-- left elbow link -->
  <link name="l_el_yaw_link">
    <visual>
      <xacro:insert_mesh_l_el_yaw_link />
    </visual>
    <collision>
      <xacro:insert_meshcol_l_el_yaw_link />
    </collision>
    <inertial>
      <xacro:insert_inertia_l_el_yaw_link />
    </inertial>
  </link>

  </xacro:macro>

</robot>
