<?xml version="1.0" ?>
<robot xmlns:xacro="http://ros.org/wiki/xacro">

  <!-- left leg -->
  <xacro:macro name="humanoid_l_leg" params="parent">

  <!-- left hip yaw joint -->
  <joint name="l_hip_yaw" type="revolute">
    <parent link="${parent}"/>
    <child link="l_hip_yaw_link"/>
    <origin xyz="0.000 0.105 -0.02" rpy="0 0 0" />
    <axis xyz="0 0 -1" />
    <limit effort="10" velocity="2" lower="${-pi*0.9}" upper="${pi*0.9}" />
    <dynamics damping="0.1" friction="0.0" />
  </joint>
  <xacro:insert_transmission name="l_hip_yaw" />

  <!-- left hip yaw link -->
  <link name="l_hip_yaw_link">
    <visual>
      <xacro:insert_mesh_l_hip_yaw_link />
    </visual>
    <collision>
      <xacro:insert_meshcol_l_hip_yaw_link />
    </collision>
    <inertial>
      <xacro:insert_inertia_l_hip_yaw_link />
    </inertial>
  </link>

  <!-- left hip roll joint -->
  <joint name="l_hip_roll" type="revolute">
    <parent link="l_hip_yaw_link"/>
    <child link="l_hip_roll_link"/>
    <origin xyz="0.05179 0.0 -0.0425" rpy="0.0 0.0 0.0"/>
    <axis xyz="1 0 0" />
    <limit effort="10" velocity="2" lower="${-pi*0.9}" upper="${pi*0.9}" />
    <dynamics damping="0.1" friction="0.0" />
  </joint>
  <xacro:insert_transmission name="l_hip_roll" />

  <!-- left hip roll link -->
  <link name="l_hip_roll_link">
    <visual>
      <xacro:insert_mesh_l_hip_roll_link />
    </visual>
    <collision>
      <xacro:insert_meshcol_l_hip_roll_link />
    </collision>
    <inertial>
      <xacro:insert_inertia_l_hip_roll_link />
    </inertial>
  </link>

  <!-- left hip pitch back joint -->
  <joint name="l_hip_pitch_back" type="revolute">
    <parent link="l_hip_roll_link"/>
    <child link="l_hip_pitch_back_link"/>
    <origin xyz="-0.08744 0.05279 -0.05804" rpy="0.0 0.0 0.0"/>
    <axis xyz="0 1 0" />
    <limit effort="10" velocity="2" lower="${-pi*0.9}" upper="${pi*0.9}" />
    <dynamics damping="0.1" friction="0.0" />
  </joint>
  <xacro:insert_transmission name="l_hip_pitch_back" />

  <!-- left hip pitch back link -->
  <link name="l_hip_pitch_back_link">
    <visual>
      <xacro:insert_mesh_l_hip_pitch_back_link />
    </visual>
    <collision>
      <xacro:insert_meshcol_l_hip_pitch_back_link />
    </collision>
    <inertial>
      <xacro:insert_inertia_l_hip_pitch_back_link />
    </inertial>
  </link>

  <!-- left hip pitch front joint -->
  <joint name="l_hip_pitch_front" type="revolute">
    <parent link="l_knee_link"/>
    <child link="l_hip_pitch_front_link"/>
    <origin xyz="0.0715 0.000 0.028" rpy="0 0 0" />
    <axis xyz="0 1 0" />
    <limit effort="10" velocity="2" lower="${-pi*0.9}" upper="${pi*0.9}" />
    <dynamics damping="0.1" friction="0.0" />
  </joint>
  <xacro:insert_transmission name="l_hip_pitch_front" />

  <!-- left hip pitch front link -->
  <link name="l_hip_pitch_front_link">
    <visual>
      <xacro:insert_mesh_l_hip_pitch_front_link />
    </visual>
    <collision>
      <xacro:insert_meshcol_l_hip_pitch_front_link />
    </collision>
    <inertial>
      <xacro:insert_inertia_l_hip_pitch_front_link />
    </inertial>
  </link>

  <!-- left knee joint -->
  <joint name="l_knee" type="revolute">
    <parent link="l_hip_pitch_back_link"/>
    <child link="l_knee_link"/>
    <origin xyz="0.0 0.0 -0.275" rpy="0 0 0" />
    <axis xyz="0 -1 0" />
    <limit effort="10" velocity="2" lower="${-pi*0.9}" upper="${pi*0.9}" />
    <dynamics damping="0.1" friction="0.0" />
  </joint>
  <xacro:insert_transmission name="l_knee" />
  <!-- left knee link -->
  <link name="l_knee_link">
    <visual>
      <xacro:insert_mesh_l_knee_link />
    </visual>
    <collision>
      <xacro:insert_meshcol_l_knee_link />
    </collision>
    <inertial>
      <xacro:insert_inertia_l_knee_link />
    </inertial>
  </link>

  <!-- left ankle pitch back joint -->
  <joint name="l_ank_pitch_back" type="revolute">
    <parent link="l_knee_link"/>
    <child link="l_ank_pitch_back_link"/>
    <origin xyz="0.000 0.000 -0.043992" rpy="0 0 0" />
    <axis xyz="0 1 0" />
    <limit effort="10" velocity="2" lower="${-pi*0.9}" upper="${pi*0.9}" />
    <dynamics damping="0.1" friction="0.0" />
  </joint>
  <xacro:insert_transmission name="l_ank_pitch_back" />

  <!-- left ankle pitch back link -->
  <link name="l_ank_pitch_back_link">
    <visual>
      <xacro:insert_mesh_l_ank_pitch_back_link />
    </visual>
    <collision>
      <xacro:insert_meshcol_l_ank_pitch_back_link />
    </collision>
    <inertial>
      <xacro:insert_inertia_l_ank_pitch_back_link />
    </inertial>
  </link>

  <!-- left ankle pitch front joint -->
  <joint name="l_ank_pitch_front" type="revolute">
    <parent link="l_knee_link"/>
    <child link="l_ank_pitch_front_link"/>
    <origin xyz="0.0715 0.000 -0.071992" rpy="0 0 0" />
    <axis xyz="0 1 0" />
    <limit effort="10" velocity="2" lower="${-pi*0.9}" upper="${pi*0.9}" />
    <dynamics damping="0.1" friction="0.0" />
  </joint>
  <xacro:insert_transmission name="l_ank_pitch_front" />

  <!-- left ankle pitch front link -->
  <link name="l_ank_pitch_front_link">
    <visual>
      <xacro:insert_mesh_l_ank_pitch_front_link />
    </visual>
    <collision>
      <xacro:insert_meshcol_l_ank_pitch_front_link />
    </collision>
    <inertial>
      <xacro:insert_inertia_l_ank_pitch_front_link />
    </inertial>
  </link>

  <!-- left ankle joint -->
  <joint name="l_ank" type="revolute">
    <parent link="l_ank_pitch_back_link"/>
    <child link="l_ank_link"/>
    <origin xyz="0.000 0.000 -0.275" rpy="0 0 0" />
    <axis xyz="0 -1 0" />
    <limit effort="10" velocity="2" lower="${-pi*0.9}" upper="${pi*0.9}" />
    <dynamics damping="0.1" friction="0.0" />
  </joint>
  <xacro:insert_transmission name="l_ank" />

  <!-- left ankle link -->
  <link name="l_ank_link">
    <visual>
      <xacro:insert_mesh_l_ank_link />
    </visual>
    <collision>
      <xacro:insert_meshcol_l_ank_link />
    </collision>
    <inertial>
      <xacro:insert_inertia_l_ank_link />
    </inertial>
  </link>

  <!-- left ankle roll joint -->
  <joint name="l_ank_roll" type="revolute">
    <parent link="l_ank_link"/>
    <child link="l_ank_roll_link"/>
    <origin xyz="0.08744 -0.05279 -0.05804" rpy="0 0 0" />
    <axis xyz="1 0 0" />
    <limit effort="10" velocity="2" lower="${-pi*0.9}" upper="${pi*0.9}" />
    <dynamics damping="0.1" friction="0.0" />
  </joint>
  <xacro:insert_transmission name="l_ank_roll" />

  <!-- left ankle roll link -->
  <link name="l_ank_roll_link">
    <visual>
      <xacro:insert_mesh_l_ank_roll_link />
    </visual>
    <collision>
      <xacro:insert_meshcol_l_ank_roll_link />
    </collision>
    <inertial>
      <xacro:insert_inertia_l_ank_roll_link />
    </inertial>
  </link>
    <!-- end effector left leg -->
  <joint name="end_eff_l_leg" type="fixed">
    <origin xyz="-0.051890 0 -0.045500" rpy="0 0 0"/>
    <parent link="l_ank_roll_link"/>
    <child link="end_eff_l_leg_link"/>
    <axis xyz="1 0 0" />
  </joint>
  <link name="end_eff_l_leg_link">
  </link>
  </xacro:macro>
</robot>